Workbook

Sheet Glossary
A1: Freshwater | C1: Armor Traits | E1: Eye Traits | G1: Horn Traits
A2: Pond | C2: Scaleback | E2: Ember Eyes | G2: Single Horn
A3: Lake | C3: Iron Scale | E3: Sapphire Eyes | G3: Twin Horn
A4: Reservoir | C4: Crystal Scale | E4: Golden Eyes | G4: Crown Horn
A5: River | C5: Ridgeback | E5: Blind White Eyes | G5: Curved Horn
A6: Stream | C6: Bone Plate | E6: Crystal Eyes | G6: Antler Horn
A7: Creek | C7: Stonehide | E7: Slit Pupils | G7: Frilled Horn
A8: Brook | C8: Barkhide | E8: Multi-Iris Eyes | G8: Nose Spike
A9: Canal | C9: Obsidian Scale | E9: Luminous Eyes | G9: Jaw Horn
A10: Ditch | C10: Mirror Scale | E10: Void Eyes | G10: Hook Horn
A11: Spring | C11: Serrated Scale
A12: Wetland | E12: Body Growth | G12: Mouth Traits
A13: Marsh | C13: Tail Traits | E13: Giant | G13: Fangjaw
A14: Swamp | C14: Hammer Tail | E14: Dwarf | G14: Sawtooth
A15: Oxbow Lake | C15: Spiked Tail | E15: Longbody | G15: Split Jaw
C16: Whip Tail | E16: Thickbody | G16: Reinforced Jaw
A17: Brackish Water | C17: Club Tail | E17: Deepbody | G17: Venom Fang
A18: Estuary | C18: Split Tail | E18: Broadhead | G18: Heated Teeth
A19: Delta | C19: Bladed Tail | E19: Heavy Bone | G19: Stone Teeth
A20: Lagoon | C20: Anchor Tail | E20: Massive Spine
A21: Mangrove
A22: Tidal Creek | C22: Mana Traits | E22: Claw / Fin Traits
A23: Tidal River | C23: Crystal Veins | E23: Bladefin
C24: Glowing Veins | E24: Razorfin
A25: Saltwater | C25: Mana Bloom | E25: Wingfin
A26: Ocean | C26: Arc Marks | E26: Hookfin
A27: Sea | C27: Mana Tumor | E27: Spinefin
A28: Bay | C28: Mana Scar | E28: Bonefin
A29: Gulf | C29: Runic Pattern | E29: Featherfin
A30: Sound | C30: Mana Pulse | E30: Broadfin
A31: Cove
A32: Inlet
A33: Harbor
A34: Fjord
E88: Elemental Traits
E89: Ember
E90: Frost
E91: Storm
E92: Static
E93: Venom
...

Sheet Rarity
A1: Initial | B1: Name | C1: Weight Range | D1: Base Bite | E1: Base Escape | F1: Base Mutation
A2: C | B2: Common | C2: 451-1000 | D2: 100 | E2: 0 | F2: 5
A3: UC | B3: Uncommon | C3: 201-450 | D3: 100 | E3: 0 | F3: 4
A4: R | B4: Rare | C4: 51-200 | D4: 60 | E4: 15 | F4: 3
A5: L | B5: Legendary | C5: 11-50 | D5: 20 | E5: 25 | F5: 2
A6: M | B6: Mythical | C6: 1-10 | D6: 10 | E6: 40 | F6: 1
A7: E | B7: Event | C7: 1-1000 | D7: 100 | E7: 30 | F7: 0

Sheet Bait
A1: Name | B1: Category | C1: Water | D1: Description
A2: Earthworm | B2: Worm | C2: 1.2 | D2: The basic natural bait that attract wide range of bottom-feeding fish and omnivorous fish. | E2: =_xlfn.CONCAT("('",A2,"',","'",B2,"',","'",D2,"')") -> ('Earthworm','Worm','The basic natural bait that attract wide range of bottom-feeding fish and omnivorous fish.')
A3: Nightcrawler | B3: Worm | C3: 1.2 | D3: A large and lively worm that attracts bigger fish looking for an easy prey because of its movement. | E3: =_xlfn.CONCAT("('",A3,"',","'",B3,"',","'",D3,"')") -> ('Nightcrawler','Worm','A large and lively worm that attracts bigger fish looking for an easy prey because of its movement.')
A4: Ragworm | B4: Worm | C4: 2.3 | D4: A tough marine worm that attracts aggressive predators lives in brackish and seawater. | E4: =_xlfn.CONCAT("('",A4,"',","'",B4,"',","'",D4,"')") -> ('Ragworm','Worm','A tough marine worm that attracts aggressive predators lives in brackish and seawater.')
A5: Bloodworm | B5: Worm | C5: 1,2,3 | D5: Bright red larvae rich in nutrients, irresistible to many insect-eating and bottom-feeding fish. | E5: =_xlfn.CONCAT("('",A5,"',","'",B5,"',","'",D5,"')") -> ('Bloodworm','Worm','Bright red larvae rich in nutrients, irresistible to many insect-eating and bottom-feeding fish.')
A6: Sandworm | B6: Worm | C6: 2.3 | D6: A worm living inside a sandy bottom is targeted by fish that forage on the bottom of the water. | E6: =_xlfn.CONCAT("('",A6,"',","'",B6,"',","'",D6,"')") -> ('Sandworm','Worm','A worm living inside a sandy bottom is targeted by fish that forage on the bottom of the water.')
A7: River Shrimp | B7: Crustacean | C7: 1.2 | D7: A type of crustacean favored by freshwater and brackish predators. | E7: =_xlfn.CONCAT("('",A7,"',","'",B7,"',","'",D7,"')") -> ('River Shrimp','Crustacean','A type of crustacean favored by freshwater and brackish predators.')
A8: Small Crab | B8: Crustacean | C8: 2.3 | D8: A small crustacean, a highly sought-after fish not bothered by the shell. | E8: =_xlfn.CONCAT("('",A8,"',","'",B8,"',","'",D8,"')") -> ('Small Crab','Crustacean','A small crustacean, a highly sought-after fish not bothered by the shell.')
A9: Prawn | B9: Crustacean | C9: 1,2,3 | D9: A large meaty crustacean, irresistible to omnivorous fish and predator alike. | E9: =_xlfn.CONCAT("('",A9,"',","'",B9,"',","'",D9,"')") -> ('Prawn','Crustacean','A large meaty crustacean, irresistible to omnivorous fish and predator alike.')
A10: Shrimp | B10: Crustacean | C10: 1,2,3 | D10: A small freshwater crustacean that attracts fish that hunting aquatic prey. | E10: =_xlfn.CONCAT("('",A10,"',","'",B10,"',","'",D10,"')") -> ('Shrimp','Crustacean','A small freshwater crustacean that attracts fish that hunting aquatic prey.')
A11: Crayfish | B11: Crustacean | C11: 1 | D11: A freshwater crustacean is highly effective in attracting large predatory fish lurking near the bottom. | E11: =_xlfn.CONCAT("('",A11,"',","'",B11,"',","'",D11,"')") -> ('Crayfish','Crustacean','A freshwater crustacean is highly effective in attracting large predatory fish lurking near the bottom.')
A12: Beetle Grub | B12: Larvae | C12: 1 | D12: A soft-bodied larva packed with protein necessary to attracts insect lover fish. | E12: =_xlfn.CONCAT("('",A12,"',","'",B12,"',","'",D12,"')") -> ('Beetle Grub','Larvae','A soft-bodied larva packed with protein necessary to attracts insect lover fish.')
A13: Mealworm | B13: Larvae | C13: 1 | D13: A wriggling larvae that appeals to fish hunting for food near the surface of the water. | E13: =_xlfn.CONCAT("('",A13,"',","'",B13,"',","'",D13,"')") -> ('Mealworm','Larvae','A wriggling larvae that appeals to fish hunting for food near the surface of the water.')
A14: Dragonfly Nymph | B14: Larvae | C14: 1 | D14: An aquatic insect larva is preyed upon by many freshwater fish. | E14: =_xlfn.CONCAT("('",A14,"',","'",B14,"',","'",D14,"')") -> ('Dragonfly Nymph','Larvae','An aquatic insect larva is preyed upon by many freshwater fish.')
A15: Water Beetle Larva | B15: Larvae | C15: 1 | D15: A juicy aquatic larva that is hunted by fish searching for underwater insects. | E15: =_xlfn.CONCAT("('",A15,"',","'",B15,"',","'",D15,"')") -> ('Water Beetle Larva','Larvae','A juicy aquatic larva that is hunted by fish searching for underwater insects.')
A16: Superworm | B16: Larvae | C16: 1 | D16: A larger worm that attracts bigger insectivorous fish. | E16: =_xlfn.CONCAT("('",A16,"',","'",B16,"',","'",D16,"')") -> ('Superworm','Larvae','A larger worm that attracts bigger insectivorous fish.')
A17: Grasshopper | B17: Insect | C17: 1.2 | D17: A surface insect that draws attention from fish that are waiting for an insect to fall into the water. | E17: =_xlfn.CONCAT("('",A17,"',","'",B17,"',","'",D17,"')") -> ('Grasshopper','Insect','A surface insect that draws attention from fish that are waiting for an insect to fall into the water.')
A18: Cricket | B18: Insect | C18: 1.2 | D18: A lively insect that moves constantly, attracting opportunistic fish. | E18: =_xlfn.CONCAT("('",A18,"',","'",B18,"',","'",D18,"')") -> ('Cricket','Insect','A lively insect that moves constantly, attracting opportunistic fish.')
A19: Locust | B19: Insect | C19: 1 | D19: A large insect offering a big meal for surface-feeding fish. | E19: =_xlfn.CONCAT("('",A19,"',","'",B19,"',","'",D19,"')") -> ('Locust','Insect','A large insect offering a big meal for surface-feeding fish.')
A20: Cicada | B20: Insect | C20: 1 | D20: A seasonal insect that fish loved, eagerly waiting for it to drop to water. | E20: =_xlfn.CONCAT("('",A20,"',","'",B20,"',","'",D20,"')") -> ('Cicada','Insect','A seasonal insect that fish loved, eagerly waiting for it to drop to water.')
A21: Termite | B21: Insect | C21: 1 | D21: A small insect is often consumed by a swarm of fish or a school of fish. | E21: =_xlfn.CONCAT("('",A21,"',","'",B21,"',","'",D21,"')") -> ('Termite','Insect','A small insect is often consumed by a swarm of fish or a school of fish.')
A22: Mussel Meat | B22: Mollusk | C22: 1,2,3 | D22: Soft shellfish meat that has a strong scent that attracts bottom-feeding fish. | E22: =_xlfn.CONCAT("('",A22,"',","'",B22,"',","'",D22,"')") -> ('Mussel Meat','Mollusk','Soft shellfish meat that has a strong scent that attracts bottom-feeding fish.')
A23: Pond Snail | B23: Mollusk | C23: 1 | D23: A common freshwater mollusk that loves the taste of shelled animal. | E23: =_xlfn.CONCAT("('",A23,"',","'",B23,"',","'",D23,"')") -> ('Pond Snail','Mollusk','A common freshwater mollusk that loves the taste of shelled animal.')
A24: Clam Meat | B24: Mollusk | C24: 1 | D24: Tender clam meat that releases a scent, irresistible to bottom-feeding fish, even humans. | E24: =_xlfn.CONCAT("('",A24,"',","'",B24,"',","'",D24,"')") -> ('Clam Meat','Mollusk','Tender clam meat that releases a scent, irresistible to bottom-feeding fish, even humans.')
A25: Cockle Meat | B25: Mollusk | C25: 2.3 | D25: A salty shellfish popular among brackish and coastal fish. | E25: =_xlfn.CONCAT("('",A25,"',","'",B25,"',","'",D25,"')") -> ('Cockle Meat','Mollusk','A salty shellfish popular among brackish and coastal fish.')
A26: Oyster Meat | B26: Mollusk | C26: 2.3 | D26: Rich, oily meat that attracts fish relying on scent to locate their food. | E26: =_xlfn.CONCAT("('",A26,"',","'",B26,"',","'",D26,"')") -> ('Oyster Meat','Mollusk','Rich, oily meat that attracts fish relying on scent to locate their food.')
A27: Minnow | B27: Fish | C27: 1.2 | D27: A live baitfish that attracts larger fish that are hunting small fish. | E27: =_xlfn.CONCAT("('",A27,"',","'",B27,"',","'",D27,"')") -> ('Minnow','Fish','A live baitfish that attracts larger fish that are hunting small fish.')
A28: Sardine | B28: Fish | C28: 2.3 | D28: An oily baitfish that produces a scent trail irresistible to marine predators. | E28: =_xlfn.CONCAT("('",A28,"',","'",B28,"',","'",D28,"')") -> ('Sardine','Fish','An oily baitfish that produces a scent trail irresistible to marine predators.')
A29: Anchovy | B29: Fish | C29: 2.3 | D29: A small baitfish is attractive to schooling predators. | E29: =_xlfn.CONCAT("('",A29,"',","'",B29,"',","'",D29,"')") -> ('Anchovy','Fish','A small baitfish is attractive to schooling predators.')
A30: Juvenile Carp | B30: Fish | C30: 1 | D30: A small carp that attracts larger freshwater predators. | E30: =_xlfn.CONCAT("('",A30,"',","'",B30,"',","'",D30,"')") -> ('Juvenile Carp','Fish','A small carp that attracts larger freshwater predators.')
A31: Juvenile Perch | B31: Fish | C31: 1 | D31: A natural prey for some large carnivorous fish. | E31: =_xlfn.CONCAT("('",A31,"',","'",B31,"',","'",D31,"')") -> ('Juvenile Perch','Fish','A natural prey for some large carnivorous fish.')
A32: Beef Meat | B32: Meat | C32: 1 | D32: A chunk of meat whose strong scent is really effective to attracts scavenger and opportunistic predator fish. | E32: =_xlfn.CONCAT("('",A32,"',","'",B32,"',","'",D32,"')") -> ('Beef Meat','Meat','A chunk of meat whose strong scent is really effective to attracts scavenger and opportunistic predator fish.')
A33: Pork Meat | B33: Meat | C33: 1 | D33: Fatty meat for an unusual fish that is not afraid to try anything new. | E33: =_xlfn.CONCAT("('",A33,"',","'",B33,"',","'",D33,"')") -> ('Pork Meat','Meat','Fatty meat for an unusual fish that is not afraid to try anything new.')
A34: Chicken Meat | B34: Meat | C34: 1,2,3 | D34: Tender meat is used to attract omnivorous and predator fish alike. | E34: =_xlfn.CONCAT("('",A34,"',","'",B34,"',","'",D34,"')") -> ('Chicken Meat','Meat','Tender meat is used to attract omnivorous and predator fish alike.')
A35: Chicken Heart | B35: Meat | C35: 1,2,3 | D35: Dense and durable bait that stays on the hook even after being peck by predators. | E35: =_xlfn.CONCAT("('",A35,"',","'",B35,"',","'",D35,"')") -> ('Chicken Heart','Meat','Dense and durable bait that stays on the hook even after being peck by predators.')
A36: Pork Intestine | B36: Meat | C36: 1 | D36: Tough, oily intestine that release strong scent to attract big predator. | E36: =_xlfn.CONCAT("('",A36,"',","'",B36,"',","'",D36,"')") -> ('Pork Intestine','Meat','Tough, oily intestine that release strong scent to attract big predator.')
A37: Bread | B37: Produce | C37: 1 | D37: A simple bait to catch herbivorous and omnivorous fish. | E37: =_xlfn.CONCAT("('",A37,"',","'",B37,"',","'",D37,"')") -> ('Bread','Produce','A simple bait to catch herbivorous and omnivorous fish.')
A38: Dough | B38: Produce | C38: 1 | D38: Soft and moldable bait commonly used for fish that feed on plants and grain matter. | E38: =_xlfn.CONCAT("('",A38,"',","'",B38,"',","'",D38,"')") -> ('Dough','Produce','Soft and moldable bait commonly used for fish that feed on plants and grain matter.')
A39: Sweet Corn | B39: Produce | C39: 1 | D39: Attract curious omnivorous fish with its color and sweet scent. | E39: =_xlfn.CONCAT("('",A39,"',","'",B39,"',","'",D39,"')") -> ('Sweet Corn','Produce','Attract curious omnivorous fish with its color and sweet scent.')
A40: Rice | B40: Produce | C40: 1 | D40: Small grain is occasionally eaten by fish lived near farm water. | E40: =_xlfn.CONCAT("('",A40,"',","'",B40,"',","'",D40,"')") -> ('Rice','Produce','Small grain is occasionally eaten by fish lived near farm water.')
...

Sheet Rod
A1: Name | B1: Level | C1: Description
A2: Bamboo Pole | B2: 1 | C2: The most basic fishing pole, perfect for a beginner who is learning the art of fishing. Lightweight and surprisingly durable. | D2: =_xlfn.CONCAT("('",A2,"',",B2,",","'",C2,"'),") -> ('Bamboo Pole',1,'The most basic fishing pole, perfect for a beginner who is learning the art of fishing. Lightweight and surprisingly durable.'),
A3: Reed Pole | B3: 1 | C3: Pole that was crafted by bundling a bunch of reeds together. Lightweight rod that is easy to carry, but lacks power. | D3: =_xlfn.CONCAT("('",A3,"',",B3,",","'",C3,"'),") -> ('Reed Pole',1,'Pole that was crafted by bundling a bunch of reeds together. Lightweight rod that is easy to carry, but lacks power.'),
A4: Willow Pole | B4: 1 | C4: Made from a flexible willow wood, it bends easily under pressure, helping it from snapping. | D4: =_xlfn.CONCAT("('",A4,"',",B4,",","'",C4,"'),") -> ('Willow Pole',1,'Made from a flexible willow wood, it bends easily under pressure, helping it from snapping.'),
A5: Hazel Pole | B5: 1 | C5: A sturdy pole, valued for its balance of strength and flexibility, making it a good choice for everyday uses. | D5: =_xlfn.CONCAT("('",A5,"',",B5,",","'",C5,"'),") -> ('Hazel Pole',1,'A sturdy pole, valued for its balance of strength and flexibility, making it a good choice for everyday uses.'),
A6: Ash Pole | B6: 1 | C6: Made from a resilient ash wood, this pole offers excellent durability and reliable performance in a variety of water. | D6: =_xlfn.CONCAT("('",A6,"',",B6,",","'",C6,"'),") -> ('Ash Pole',1,'Made from a resilient ash wood, this pole offers excellent durability and reliable performance in a variety of water.'),
A7: Hickory Pole | B7: 1 | C7: Built from a dense hickory wood, this pole is favored by fishermen that trying to catch big predator fish. | D7: =_xlfn.CONCAT("('",A7,"',",B7,",","'",C7,"'),") -> ('Hickory Pole',1,'Built from a dense hickory wood, this pole is favored by fishermen that trying to catch big predator fish.'),
A8: Birch Rod | B8: 2 | C8: A lightweight rod with a smooth pole, offering improved handling during long periods of fishing trips. | D8: =_xlfn.CONCAT("('",A8,"',",B8,",","'",C8,"'),") -> ('Birch Rod',2,'A lightweight rod with a smooth pole, offering improved handling during long periods of fishing trips.'),
A9: Maple Rod | B9: 2 | C9: Carved from a hard maple wood, this well-balanced rod provides dependable control necessary to catch a big fish. | D9: =_xlfn.CONCAT("('",A9,"',",B9,",","'",C9,"'),") -> ('Maple Rod',2,'Carved from a hard maple wood, this well-balanced rod provides dependable control necessary to catch a big fish.'),
A10: Elm Rod | B10: 2 | C10: Known for its durability and resistance to splitting, the elm rod can withstand repeated use even in more demanding conditions. | D10: =_xlfn.CONCAT("('",A10,"',",B10,",","'",C10,"'),") -> ('Elm Rod',2,'Known for its durability and resistance to splitting, the elm rod can withstand repeated use even in more demanding conditions.'),
A11: Cedar Rod | B11: 2 | C11: Crafted from an aromatic cedar wood, this lightweight rod naturally resist moisture and decay making it ideal for fishing at a damp environment | D11: =_xlfn.CONCAT("('",A11,"',",B11,",","'",C11,"'),") -> ('Cedar Rod',2,'Crafted from an aromatic cedar wood, this lightweight rod naturally resist moisture and decay making it ideal for fishing at a damp environment'),
A12: Walnut Rod | B12: 2 | C12: A finely crafted rod using walnut wood, this rod has an elegant appearance and dependable strength for catching larger fish. | D12: =_xlfn.CONCAT("('",A12,"',",B12,",","'",C12,"'),") -> ('Walnut Rod',2,'A finely crafted rod using walnut wood, this rod has an elegant appearance and dependable strength for catching larger fish.'),
A13: Juniper Rod | B13: 3 | C13: Made from resilient juniper wood, making it a great rod naturally resistant to the elements. | D13: =_xlfn.CONCAT("('",A13,"',",B13,",","'",C13,"'),") -> ('Juniper Rod',3,'Made from resilient juniper wood, making it a great rod naturally resistant to the elements.'),
... A19: Crimson Wood Rod | B19: 4 | C19: Native to the woods of Seran forest, this crimson rod can withstand the harshest battle among the biggest fish in Endral. | D19: =_xlfn.CONCAT("('",A19,"',",B19,",","'",C19,"'),") -> ('Crimson Wood Rod',4,'Native to the woods of Seran forest, this crimson rod can withstand the harshest battle among the biggest fish in Endral. '),

Sheet Fish
A1: Name | B1: Water | C1: Type | D1: Rarity | E1: Base Weight | F1: Min Weight | G1: Max Weight | H1: Min Length | I1: Max Length | J1: Description | K1: City | L1: Season | M1: Location | N1: Water ID | O1: Rarity ID
A2: Banded Archerfish | B2: Brackish | C2: Archer | D2: Common | E2: 875 | F2: 0.1 | G2: 1 | H2: 5 | I2: 30 | J2: Known for its extraordinary marksmanship, the archerfish can accurately spit streams of water several body lengths to dislodge unsuspecting prey. | K2: All | L2: Summer, Dry | M2: Purba Mangrove, Ægir Fjord, Evrys Estuary, Seribu Arus Estuary | N2: {=_xlfn.IFS(B2="Freshwater",1,B2="Brackish",2,B2="Seawater",3)} -> 2 | O2: {=_xlfn.IFS(D2="Common",1,D2="Uncommon",2,D2="Rare",3,D2="Legendary",4,D2="Mythical",5,D2="Event",6)} -> 1 | P2: =_xlfn.CONCAT("('",A2,"',",N2,",",O2,",",E2,",",F2,",",G2,",",H2,",",I2,",","'",J2,"'),") -> ('Banded Archerfish',2,1,875,0.1,1,5,30,'Known for its extraordinary marksmanship, the archerfish can accurately spit streams of water several body lengths to dislodge unsuspecting prey.'),
A3: Northern Archerfish | B3: Brackish | C3: Archer | D3: Uncommon | E3: 350 | F3: 0.1 | G3: 1 | H3: 6 | I3: 40 | J3: The largest of the archerfish, sporting a deeper body and irregular dark markings. Its powerful water jets and impressive size make it a formidable hunter of mangrove shores. | K3: All | L3: Summer, Dry | M3: Ægir Fjord, Seribu Arus Estuary | N3: {=_xlfn.IFS(B3="Freshwater",1,B3="Brackish",2,B3="Seawater",3)} -> 2 | O3: {=_xlfn.IFS(D3="Common",1,D3="Uncommon",2,D3="Rare",3,D3="Legendary",4,D3="Mythical",5,D3="Event",6)} -> 2 | P3: =_xlfn.CONCAT("('",A3,"',",N3,",",O3,",",E3,",",F3,",",G3,",",H3,",",I3,",","'",J3,"'),") -> ('Northern Archerfish',2,2,350,0.1,1,6,40,'The largest of the archerfish, sporting a deeper body and irregular dark markings. Its powerful water jets and impressive size make it a formidable hunter of mangrove shores.'),
A4: Black Bream | B4: Brackish | C4: Bream | D4: Uncommon | E4: 350 | F4: 0.5 | G4: 4 | H4: 23 | I4: 60 | J4: A dark bronze estuarine bream with a deep body, known for its adaptability and strong fighting ability despite its modest size. | K4: All | L4: Spring, Autumn | M4: Purba Mangrove, Ægir Fjord, Evrys Estuary, Seribu Arus Estuary | N4: {=_xlfn.IFS(B4="Freshwater",1,B4="Brackish",2,B4="Seawater",3)} -> 2 | O4: {=_xlfn.IFS(D4="Common",1,D4="Uncommon",2,D4="Rare",3,D4="Legendary",4,D4="Mythical",5,D4="Event",6)} -> 2 | P4: =_xlfn.CONCAT("('",A4,"',",N4,",",O4,",",E4,",",F4,",",G4,",",H4,",",I4,",","'",J4,"'),") -> ('Black Bream',2,2,350,0.5,4,23,60,'A dark bronze estuarine bream with a deep body, known for its adaptability and strong fighting ability despite its modest size.'),
A5: Tarwhine Bream | B5: Brackish | C5: Bream | D5: Uncommon | E5: 450 | F5: 0.75 | G5: 4.5 | H5: 20 | I5: 58 | J5: A sleek silver bream with bright yellow fins, thriving in estuaries and coastal waters while feeding on small bottom-dwelling prey. | K5: All | L5: Autumn | M5: Purba Mangrove, Evrys Estuary | N5: {=_xlfn.IFS(B5="Freshwater",1,B5="Brackish",2,B5="Seawater",3)} -> 2 | O5: {=_xlfn.IFS(D5="Common",1,D5="Uncommon",2,D5="Rare",3,D5="Legendary",4,D5="Mythical",5,D5="Event",6)} -> 2 | P5: =_xlfn.CONCAT("('",A5,"',",N5,",",O5,",",E5,",",F5,",",G5,",",H5,",",I5,",","'",J5,"'),") -> ('Tarwhine Bream',2,2,450,0.75,4.5,20,58,'A sleek silver bream with bright yellow fins, thriving in estuaries and coastal waters while feeding on small bottom-dwelling prey.'),
A6: Hardhead Catfish | B6: Brackish | C6: Catfish | D6: Uncommon | E6: 275 | F6: 0.45 | G6: 3 | H6: 15 | I6: 64 | J6: Hardhead catfish are generally regarded as an undesirable catch because of the risk associated with handling the venomous fish. | K6: Seran, Tidehaven | L6: Dry, Autumn | M6: Purba Mangrove, Ægir Fjord | N6: {=_xlfn.IFS(B6="Freshwater",1,B6="Brackish",2,B6="Seawater",3)} -> 2 | O6: {=_xlfn.IFS(D6="Common",1,D6="Uncommon",2,D6="Rare",3,D6="Legendary",4,D6="Mythical",5,D6="Event",6)} -> 2 | P6: =_xlfn.CONCAT("('",A6,"',",N6,",",O6,",",E6,",",F6,",",G6,",",H6,",",I6,",","'",J6,"'),") -> ('Hardhead Catfish',2,2,275,0.45,3,15,64,'Hardhead catfish are generally regarded as an undesirable catch because of the risk associated with handling the venomous fish.'),
A7: Gafftopsail Catfish | B7: Brackish | C7: Catfish | D7: Uncommon | E7: 210 | F7: 1.2 | G7: 5 | H7: 12 | I7: 70 | J7: The gafftopsail catfish is blue-grey to dark brown with a light grey belly. Its appearance is typical for a catfish except for the deeply forked tail and the venomous, serrated spines. | K7: Tidehaven | L7: Summer, Autumn | M7: Ægir Fjord | N7: {=_xlfn.IFS(B7="Freshwater",1,B7="Brackish",2,B7="Seawater",3)} -> 2 | O7: {=_xlfn.IFS(D7="Common",1,D7="Uncommon",2,D7="Rare",3,D7="Legendary",4,D7="Mythical",5,D7="Event",6)} -> 2 | P7: =_xlfn.CONCAT("('",A7,"',",N7,",",O7,",",E7,",",F7,",",G7,",",H7,",",I7,",","'",J7,"'),") -> ('Gafftopsail Catfish',2,2,210,1.2,5,12,70,'The gafftopsail catfish is blue-grey to dark brown with a light grey belly. Its appearance is typical for a catfish except for the deeply forked tail and the venomous, serrated spines.'),
A8: Green Chromide | B8: Brackish | C8: Cichlid | D8: Common | E8: 850 | F8: 0.1 | G8: 2 | H8: 7.5 | I8: 40 | J8: It eats mainly aquatic plants, including filamentous algae and diatoms, but it consumes the occasional mollusk and other animal matter. | K8: Rosegleam, Tidehaven | L8: Spring, Autumn | M8: Ægir Fjord | N8: {=_xlfn.IFS(B8="Freshwater",1,B8="Brackish",2,B8="Seawater",3)} -> 2 | O8: {=_xlfn.IFS(D8="Common",1,D8="Uncommon",2,D8="Rare",3,D8="Legendary",4,D8="Mythical",5,D8="Event",6)} -> 1 | P8: =_xlfn.CONCAT("('",A8,"',",N8,",",O8,",",E8,",",F8,",",G8,",",H8,",",I8,",","'",J8,"'),") -> ('Green Chromide',2,1,850,0.1,2,7.5,40,'It eats mainly aquatic plants, including filamentous algae and diatoms, but it consumes the occasional mollusk and other animal matter.'),
A9: Orange Chromide | B9: Brackish | C9: Cichlid | D9: Uncommon | E9: 300 | F9: 0.1 | G9: 0.3 | H9: 2 | I9: 10 | J9: A vivid orange cichlid that thrives in brackish lagoons and estuaries, where it grazes on algae and hunts tiny aquatic creatures among submerged vegetation. | K9: All | L9: Spring, Summer | M9: Purba Mangrove, Ægir Fjord, Evrys Estuary, Seribu Arus Estuary | N9: {=_xlfn.IFS(B9="Freshwater",1,B9="Brackish",2,B9="Seawater",3)} -> 2 | O9: {=_xlfn.IFS(D9="Common",1,D9="Uncommon",2,D9="Rare",3,D9="Legendary",4,D9="Mythical",5,D9="Event",6)} -> 2 | P9: =_xlfn.CONCAT("('",A9,"',",N9,",",O9,",",E9,",",F9,",",G9,",",H9,",",I9,",","'",J9,"'),") -> ('Orange Chromide',2,2,300,0.1,0.3,2,10,'A vivid orange cichlid that thrives in brackish lagoons and estuaries, where it grazes on algae and hunts tiny aquatic creatures among submerged vegetation.'),
A10: Blue Tilapia | B10: Brackish | C10: Cichlid | D10: Common | E10: 600 | F10: 0.5 | G10: 5 | H10: 9 | I10: 55 | J10: It grazes on algae and aquatic vegetation while readily adapting to new habitats, making it both abundant and highly resilient. | K10: Rosegleam, Tidehaven | L10: Spring, Autumn | M10: Ægir Fjord | N10: {=_xlfn.IFS(B10="Freshwater",1,B10="Brackish",2,B10="Seawater",3)} -> 2 | O10: {=_xlfn.IFS(D10="Common",1,D10="Uncommon",2,D10="Rare",3,D10="Legendary",4,D10="Mythical",5,D10="Event",6)} -> 1 | P10: =_xlfn.CONCAT("('",A10,"',",N10,",",O10,",",E10,",",F10,",",G10,",",H10,",",I10,",","'",J10,"'),") -> ('Blue Tilapia',2,1,600,0.5,5,9,55,'It grazes on algae and aquatic vegetation while readily adapting to new habitats, making it both abundant and highly resilient.'),
A11: Black Tilapia | B11: Brackish | C11: Cichlid | D11: Common | E11: 550 | F11: 0.7 | G11: 3.2 | H11: 7 | I11: 50 | J11: The most common tilapia in Endral, it has a long upper fins, the front part of which have spines. | K11: Ourea, Seran | L11: Summer, Monsoon | M11: Purba Mangrove, Evrys Estuary | N11: {=_xlfn.IFS(B11="Freshwater",1,B11="Brackish",2,B11="Seawater",3)} -> 2 | O11: {=_xlfn.IFS(D11="Common",1,D11="Uncommon",2,D11="Rare",3,D11="Legendary",4,D11="Mythical",5,D11="Event",6)} -> 1 | P11: =_xlfn.CONCAT("('",A11,"',",N11,",",O11,",",E11,",",F11,",",G11,",",H11,",",I11,",","'",J11,"'),") -> ('Black Tilapia',2,1,550,0.7,3.2,7,50,'The most common tilapia in Endral, it has a long upper fins, the front part of which have spines.'),
A12: Hogchoker | B12: Brackish | C12: Flatfish | D12: Common | E12: 650 | F12: 0.1 | G12: 0.5 | H12: 5 | I12: 28 | J12: The overall body of this fish color is often broken by a series of spots and thin stripes, which can be lighter or darker than the main body color. | K12: Seran, Rosegleam | L12: Dry, Summer, Autumn | M12: Seribu Arus Estuary | N12: {=_xlfn.IFS(B12="Freshwater",1,B12="Brackish",2,B12="Seawater",3)} -> 2 | O12: {=_xlfn.IFS(D12="Common",1,D12="Uncommon",2,D12="Rare",3,D12="Legendary",4,D12="Mythical",5,D12="Event",6)} -> 1 | P12: =_xlfn.CONCAT("('",A12,"',",N12,",",O12,",",E12,",",F12,",",G12,",",H12,",",I12,",","'",J12,"'),") -> ('Hogchoker',2,1,650,0.1,0.5,5,28,'The overall body of this fish color is often broken by a series of spots and thin stripes, which can be lighter or darker than the main body color.'),
A13: Four-eyed Fish | B13: Brackish | C13: Four Eyed | D13: Uncommon | E13: 320 | F13: 0.1 | G13: 1 | H13: 5 | I13: 30 | J13: Four-eyed fish have only two eyes, but the eyes are specially adapted for their surface-dwelling lifestyle. | K13: Seran, Tidehaven | L13: Dry, Summer, Autumn | M13: Ægir Fjord, Seribu Arus Estuary | N13: {=_xlfn.IFS(B13="Freshwater",1,B13="Brackish",2,B13="Seawater",3)} -> 2 | O13: {=_xlfn.IFS(D13="Common",1,D13="Uncommon",2,D13="Rare",3,D13="Legendary",4,D13="Mythical",5,D13="Event",6)} -> 2 | P13: =_xlfn.CONCAT("('",A13,"',",N13,",",O13,",",E13,",",F13,",",G13,",",H13,",",I13,",","'",J13,"'),") -> ('Four-eyed Fish',2,2,320,0.1,1,5,30,'Four-eyed fish have only two eyes, but the eyes are specially adapted for their surface-dwelling lifestyle.'),
A14: Giant Mudskipper | B14: Brackish | C14: Goby | D14: Common | E14: 650 | F14: 0.1 | G14: 1 | H14: 5 | I14: 28.5 | J14: A giant amphibious goby that prowls muddy shores and mangrove forests, skillfully walking on land and leaping between tidal pools in search of prey | K14: Seran | L14: Dry | M14: Purba Mangrove, Seribu Arus Estuary | N14: {=_xlfn.IFS(B14="Freshwater",1,B14="Brackish",2,B14="Seawater",3)} -> 2 | O14: {=_xlfn.IFS(D14="Common",1,D14="Uncommon",2,D14="Rare",3,D14="Legendary",4,D14="Mythical",5,D14="Event",6)} -> 1 | P14: =_xlfn.CONCAT("('",A14,"',",N14,",",O14,",",E14,",",F14,",",G14,",",H14,",",I14,",","'",J14,"'),") -> ('Giant Mudskipper',2,1,650,0.1,1,5,28.5,'A giant amphibious goby that prowls muddy shores and mangrove forests, skillfully walking on land and leaping between tidal pools in search of prey'),
A15: Dragon Goby | B15: Brackish | C15: Goby | D15: Rare | E15: 100 | F15: 0.1 | G15: 0.5 | H15: 8 | I15: 61 | J15: Dragon Goby is said to be a baby water dragon in its infancy. This fish has a long, slender, eel-like body. | K15: Seran | L15: Monsoon | M15: Seribu Arus Estuary | N15: {=_xlfn.IFS(B15="Freshwater",1,B15="Brackish",2,B15="Seawater",3)} -> 2 | O15: {=_xlfn.IFS(D15="Common",1,D15="Uncommon",2,D15="Rare",3,D15="Legendary",4,D15="Mythical",5,D15="Event",6)} -> 3 | P15: =_xlfn.CONCAT("('",A15,"',",N15,",",O15,",",E15,",",F15,",",G15,",",H15,",",I15,",","'",J15,"'),") -> ('Dragon Goby',2,3,100,0.1,0.5,8,61,'Dragon Goby is said to be a baby water dragon in its infancy. This fish has a long, slender, eel-like body.'),
A16: Knight Goby | B16: Brackish | C16: Goby | D16: Uncommon | E16: 251 | F16: 0.1 | G16: 1 | H16: 1 | I16: 9 | J16: This goby has a speckled pattern and an armored look reminiscent of a chainmal worn by a knight. | K16: Seran, Tidehaven | L16: Dry, Autumn | M16: Purba mangrove, Ægir Fjord, Seribu Arus Estuary | N16: {=_xlfn.IFS(B16="Freshwater",1,B16="Brackish",2,B16="Seawater",3)} -> 2 | O16: {=_xlfn.IFS(D16="Common",1,D16="Uncommon",2,D16="Rare",3,D16="Legendary",4,D16="Mythical",5,D16="Event",6)} -> 2 | P16: =_xlfn.CONCAT("('",A16,"',",N16,",",O16,",",E16,",",F16,",",G16,",",H16,",",I16,",","'",J16,"'),") -> ('Knight Goby',2,2,251,0.1,1,1,9,'This goby has a speckled pattern and an armored look reminiscent of a chainmal worn by a knight.'),
A17: Bumblebee Goby | B17: Brackish | C17: Goby | D17: Rare | E17: 111 | F17: 0.1 | G17: 1 | H17: 1 | I17: 4 | J17: A miniature goby known for its bold yellow-and-black stripes. Despite its small size, it is an active predator that patrols muddy bottoms and dense vegetation in search of tiny prey. | K17: Seran, Rosegleam, Tidehaven | L17: Dry, Autumn | M17: Purba mangrove, Ægir Fjord | N17: {=_xlfn.IFS(B17="Freshwater",1,B17="Brackish",2,B17="Seawater",3)} -> 2 | O17: {=_xlfn.IFS(D17="Common",1,D17="Uncommon",2,D17="Rare",3,D17="Legendary",4,D17="Mythical",5,D17="Event",6)} -> 3 | P17: =_xlfn.CONCAT("('",A17,"',",N17,",",O17,",",E17,",",F17,",",G17,",",H17,",",I17,",","'",J17,"'),") -> ('Bumblebee Goby',2,3,111,0.1,1,1,4,'A miniature goby known for its bold yellow-and-black stripes. Despite its small size, it is an active predator that patrols muddy bottoms and dense vegetation in search of tiny prey.'),
A18: Marble Goby | B18: Brackish | C18: Goby | D18: Uncommon | E18: 300 | F18: 1 | G18: 7.5 | H18: 10 | I18: 65 | J18: It is a highly popular fish among rich families, said to be best eaten after a childbirth or Chirurgy. | K18: Rosegleam, Tidehaven | L18: Autumn, Winter | M18: Ægir Fjord | N18: {=_xlfn.IFS(B18="Freshwater",1,B18="Brackish",2,B18="Seawater",3)} -> 2 | O18: {=_xlfn.IFS(D18="Common",1,D18="Uncommon",2,D18="Rare",3,D18="Legendary",4,D18="Mythical",5,D18="Event",6)} -> 2 | P18: =_xlfn.CONCAT("('",A18,"',",N18,",",O18,",",E18,",",F18,",",G18,",",H18,",",I18,",","'",J18,"'),") -> ('Marble Goby',2,2,300,1,7.5,10,65,'It is a highly popular fish among rich families, said to be best eaten after a childbirth or Chirurgy.'),
A19: Wrestling Halfbeak | B19: Brackish | C19: Halfbeak | D19: Common | E19: 630 | F19: 0.1 | G19: 0.3 | H19: 1.2 | I19: 8 | J19: Wrestling halfbeaks are surface-feeding fish and feed on a variety of small invertebrates, including crustaceans and insect larvae. | K19: Seran, Tidehaven | L19: Dry, Autumn | M19: Purba mangrove, Ægir Fjord, Seribu Arus Estuary | N19: {=_xlfn.IFS(B19="Freshwater",1,B19="Brackish",2,B19="Seawater",3)} -> 2 | O19: {=_xlfn.IFS(D19="Common",1,D19="Uncommon",2,D19="Rare",3,D19="Legendary",4,D19="Mythical",5,D19="Event",6)} -> 1 | P19: =_xlfn.CONCAT("('",A19,"',",N19,",",O19,",",E19,",",F19,",",G19,",",H19,",",I19,",","'",J19,"'),") -> ('Wrestling Halfbeak',2,1,630,0.1,0.3,1.2,8,'Wrestling halfbeaks are surface-feeding fish and feed on a variety of small invertebrates, including crustaceans and insect larvae.'),
A20: Milkfish | B20: Brackish | C20: Milkfish | D20: Common | E20: 625 | F20: 1.2 | G20: 20 | H20: 90 | I20: 180 | J20: The milkfish is an important seafood in Seran and some Ourea places. This fish is infamous for being much bonier than other food fishes. | K20: Ourea, Seran | L20: Summer, Monsoon | M20: Evrys Estuary, Seribu Arus Estuary | N20: {=_xlfn.IFS(B20="Freshwater",1,B20="Brackish",2,B20="Seawater",3)} -> 2 | O20: {=_xlfn.IFS(D20="Common",1,D20="Uncommon",2,D20="Rare",3,D20="Legendary",4,D20="Mythical",5,D20="Event",6)} -> 1 | P20: =_xlfn.CONCAT("('",A20,"',",N20,",",O20,",",E20,",",F20,",",G20,",",H20,",",I20,",","'",J20,"'),") -> ('Milkfish',2,1,625,1.2,20,90,180,'The milkfish is an important seafood in Seran and some Ourea places. This fish is infamous for being much bonier than other food fishes.'),
A21: Tidehaven Moony | B21: Brackish | C21: Moony | D21: Common | E21: 555 | F21: 0.1 | G21: 1 | H21: 7 | I21: 25 | J21: A silvery schooling fish with a diamond-shaped body and striking black markings native to Tidehaven water. | K21: Tidehaven | L21: Autumn | M21: Ægir Fjord | N21: {=_xlfn.IFS(B21="Freshwater",1,B21="Brackish",2,B21="Seawater",3)} -> 2 | O21: {=_xlfn.IFS(D21="Common",1,D21="Uncommon",2,D21="Rare",3,D21="Legendary",4,D21="Mythical",5,D21="Event",6)} -> 1 | P21: =_xlfn.CONCAT("('",A21,"',",N21,",",O21,",",E21,",",F21,",",G21,",",H21,",",I21,",","'",J21,"'),") -> ('Tidehaven Moony',2,1,555,0.1,1,7,25,'A silvery schooling fish with a diamond-shaped body and striking black markings native to Tidehaven water.'),
A22: Silver Moony | B22: Brackish | C22: Moony | D22: Common | E22: 800 | F22: 0.1 | G22: 1 | H22: 4 | I22: 27 | J22: This fish has a bright, shiny silver color with yellowish edges to the fins, and the upper and anal fins have black tips. | K22: All | L22: Spring, Autumn | M22: Purba mangrove, Ægir Fjord, Evrys Estuary, Seribu Arus Estuary | N22: {=_xlfn.IFS(B22="Freshwater",1,B22="Brackish",2,B22="Seawater",3)} -> 2 | O22: {=_xlfn.IFS(D22="Common",1,D22="Uncommon",2,D22="Rare",3,D22="Legendary",4,D22="Mythical",5,D22="Event",6)} -> 1 | P22: =_xlfn.CONCAT("('",A22,"',",N22,",",O22,",",E22,",",F22,",",G22,",",H22,",",I22,",","'",J22,"'),") -> ('Silver Moony',2,1,800,0.1,1,4,27,'This fish has a bright, shiny silver color with yellowish edges to the fins, and the upper and anal fins have black tips.'),
A23: Striped Mullet | B23: Brackish | C23: Mullet | D23: Common | E23: 615 | F23: 1.1 | G23: 8 | H23: 30 | I23: 100 | J23: The back of the fish is olive-green, sides are silvery and shade to white towards the belly. | K23: Rosegleam, Tidehaven | L23: Summer, Autumn | M23: Ægir Fjord | N23: {=_xlfn.IFS(B23="Freshwater",1,B23="Brackish",2,B23="Seawater",3)} -> 2 | O23: {=_xlfn.IFS(D23="Common",1,D23="Uncommon",2,D23="Rare",3,D23="Legendary",4,D23="Mythical",5,D23="Event",6)} -> 1 | P23: =_xlfn.CONCAT("('",A23,"',",N23,",",O23,",",E23,",",F23,",",G23,",",H23,",",I23,",","'",J23,"'),") -> ('Striped Mullet',2,1,615,1.1,8,30,100,'The back of the fish is olive-green, sides are silvery and shade to white towards the belly.'),
A24: Needlefish | B24: Brackish | C24: Needlefish | D24: Common | E24: 800 | F24: 0.1 | G24: 0.5 | H24: 3 | I24: 30 | J24: Needlefish are slender and have a single upper fin. Their most distinctive feature is their long, narrow beak, which bears multiple sharp teeth. | K24: All | L24: Spring, Monsoon | M24: Purba mangrove, Ægir Fjord, Evrys Estuary, Seribu Arus Estuary | N24: {=_xlfn.IFS(B24="Freshwater",1,B24="Brackish",2,B24="Seawater",3)} -> 2 | O24: {=_xlfn.IFS(D24="Common",1,D24="Uncommon",2,D24="Rare",3,D24="Legendary",4,D24="Mythical",5,D24="Event",6)} -> 1 | P24: =_xlfn.CONCAT("('",A24,"',",N24,",",O24,",",E24,",",F24,",",G24,",",H24,",",I24,",","'",J24,"'),") -> ('Needlefish',2,1,800,0.1,0.5,3,30,'Needlefish are slender and have a single upper fin. Their most distinctive feature is their long, narrow beak, which bears multiple sharp teeth.'),
A25: Mangrove Jack | B25: Brackish | C25: Snapper | D25: Common | E25: 585 | F25: 2.3 | G25: 13.5 | H25: 60 | I25: 150 | J25: Coloration of the Mangrove Jack ranges from burnt orange to copper, to bronze, and dark reddish-brown, depending on its age and environment. | K25: Ourea, Seran | L25: Autumn, Dry | M25: Purba Mangrove, Evrys Estuary | N25: {=_xlfn.IFS(B25="Freshwater",1,B25="Brackish",2,B25="Seawater",3)} -> 2 | O25: {=_xlfn.IFS(D25="Common",1,D25="Uncommon",2,D25="Rare",3,D25="Legendary",4,D25="Mythical",5,D25="Event",6)} -> 1 | P25: =_xlfn.CONCAT("('",A25,"',",N25,",",O25,",",E25,",",F25,",",G25,",",H25,",",I25,",","'",J25,"'),") -> ('Mangrove Jack',2,1,585,2.3,13.5,60,150,'Coloration of the Mangrove Jack ranges from burnt orange to copper, to bronze, and dark reddish-brown, depending on its age and environment.'),
A26: Common Bream | B26: Freshwater | C26: Bream | D26: Common | E26: 950 | F26: 4 | G26: 11 | H26: 30 | I26: 86 | J26: Common bream have a black fins and silver color in young bream that turn bronze when its got older | K26: All | L26: Spring, Summer | M26: Vasikos Pond, Astrafteri Lake, Prasinos Creek, Telma Swamp, Evrys River, Iremia River, Saint Luke Pond, Prince Kaiden Reservoir, Merman Marsh, Sofia River, Kaca Lake, Seribu Arus River, Mentari Pond, Seroja Marsh, Mikil Hvitar Lake, Ormr River, Freyja River, Reyr Marsh | N26: {=_xlfn.IFS(B26="Freshwater",1,B26="Brackish",2,B26="Seawater",3)} -> 1 | O26: {=_xlfn.IFS(D26="Common",1,D26="Uncommon",2,D26="Rare",3,D26="Legendary",4,D26="Mythical",5,D26="Event",6)} -> 1 | P26: =_xlfn.CONCAT("('",A26,"',",N26,",",O26,",",E26,",",F26,",",G26,",",H26,",",I26,",","'",J26,"'),") -> ('Common Bream',1,1,950,4,11,30,86,'Common bream have a black fins and silver color in young bream that turn bronze when its got older'),
A27: White Bream | B27: Freshwater | C27: Bream | D27: Common | E27: 975 | F27: 0.25 | G27: 2 | H27: 5 | I27: 7 | J27: White Bream / Silver Bream generally inhabit the lower reaches of rivers as well as lakes and ponds with muddy bottoms and plenty of algae to feed on. | K27: All | L27: Summer, Autumn | M27: Astrafterí Lake, Telma Swamp, Evrys River, Iremia River, Prince Kaiden Reservoir, Merman Marsh, Wisp Swamp, Becket Cross Canal, Seribu Arus River, Seroja Marsh, Batu Kawah Lake, Mikil Hvitar Lake, Yrvir Swamp | N27: {=_xlfn.IFS(B27="Freshwater",1,B27="Brackish",2,B27="Seawater",3)} -> 1 | O27: {=_xlfn.IFS(D27="Common",1,D27="Uncommon",2,D27="Rare",3,D27="Legendary",4,D27="Mythical",5,D27="Event",6)} -> 1 | P27: =_xlfn.CONCAT("('",A27,"',",N27,",",O27,",",E27,",",F27,",",G27,",",H27,",",I27,",","'",J27,"'),") -> ('White Bream',1,1,975,0.25,2,5,7,'White Bream / Silver Bream generally inhabit the lower reaches of rivers as well as lakes and ponds with muddy bottoms and plenty of algae to feed on.'),
A28: Vimba Bream | B28: Freshwater | C28: Bream | D28: Common | E28: 800 | F28: 1 | G28: 2 | H28: 20 | I28: 50 | J28: This fish is a deep bluish-green on the upper surface, and silvery along the flanks. The eyes are yellow, and the pectoral and pelvic fins have reddish-yellow bases. | K28: Rosegleam, Tidehaven | L28: Spring, Summer | M28: Prince Kaiden Reservoir, Merman Marsh, Wisp Swamp, Becket Cross Canal, Ormr River, Freyja River, Jotunn Cave, Reyr Marsh, Yrvir Swamp | N28: {=_xlfn.IFS(B28="Freshwater",1,B28="Brackish",2,B28="Seawater",3)} -> 1 | O28: {=_xlfn.IFS(D28="Common",1,D28="Uncommon",2,D28="Rare",3,D28="Legendary",4,D28="Mythical",5,D28="Event",6)} -> 1 | P28: =_xlfn.CONCAT("('",A28,"',",N28,",",O28,",",E28,",",F28,",",G28,",",H28,",",I28,",","'",J28,"'),") -> ('Vimba Bream',1,1,800,1,2,20,50,'This fish is a deep bluish-green on the upper surface, and silvery along the flanks. The eyes are yellow, and the pectoral and pelvic fins have reddish-yellow bases.'),
A29: Blue Bream | B29: Freshwater | C29: Bream | D29: Uncommon | E29: 300 | F29: 1 | G29: 3 | H29: 25 | I29: 55 | J29: A sleek silver-blue fish that travels in large schools through deep rivers and lakes, feeding on drifting insects and tiny aquatic prey. | K29: Ourea, Rosegleam | L29: Spring, Autumn | M29: Vasikos Pond, Prasinos Creek, Theikos Spring, Saint Luke Pond, Becket Cross Canal | N29: {=_xlfn.IFS(B29="Freshwater",1,B29="Brackish",2,B29="Seawater",3)} -> 1 | O29: {=_xlfn.IFS(D29="Common",1,D29="Uncommon",2,D29="Rare",3,D29="Legendary",4,D29="Mythical",5,D29="Event",6)} -> 2 | P29: =_xlfn.CONCAT("('",A29,"',",N29,",",O29,",",E29,",",F29,",",G29,",",H29,",",I29,",","'",J29,"'),") -> ('Blue Bream',1,2,300,1,3,25,55,'A sleek silver-blue fish that travels in large schools through deep rivers and lakes, feeding on drifting insects and tiny aquatic prey.'),
A30: Common Carp | B30: Freshwater | C30: Carp | D30: Common | E30: 1000 | F30: 5 | G30: 40 | H30: 40 | I30: 110 | J30: A common carp is a widespread freshwater fish that can be found on almost every freshwater habitat. | K30: All | L30: Spring, Autumn | M30: Vasiko Pond, Prasinos Creek,, Telma Swamp, Theikos Spring, Evrys River, Iremia River, Saint Luke Pond, Prince Kaiden Reservoir, Merman Marsh, Wisp Swamp, Sofia River, Kaca Lake, Seribu Arus River, Mentari Pond, Seroja Marsh, Batu Kawah Lake, Seroja Darah Swamp, Mikill Hvitar Lake, Ormr River, Freyja River, Reyr Marsh, Yrvir Swamp | N30: {=_xlfn.IFS(B30="Freshwater",1,B30="Brackish",2,B30="Seawater",3)} -> 1 | O30: {=_xlfn.IFS(D30="Common",1,D30="Uncommon",2,D30="Rare",3,D30="Legendary",4,D30="Mythical",5,D30="Event",6)} -> 1 | P30: =_xlfn.CONCAT("('",A30,"',",N30,",",O30,",",E30,",",F30,",",G30,",",H30,",",I30,",","'",J30,"'),") -> ('Common Carp',1,1,1000,5,40,40,110,'A common carp is a widespread freshwater fish that can be found on almost every freshwater habitat.'),
A31: Grass Carp | B31: Freshwater | C31: Carp | D31: Common | E31: 550 | F31: 5 | G31: 45 | H31: 20 | I31: 95 | J31: Grass Carp eggs require a long river to survive, and the eggs will be considered dead when they hit the bottom of the river. | K31: Seran | L31: Monsoon | M31: Kaca Lake, Seribu Arus River, Mentari Pond, Seroja Marsh, Seroja Darah Swamp | N31: {=_xlfn.IFS(B31="Freshwater",1,B31="Brackish",2,B31="Seawater",3)} -> 1 | O31: {=_xlfn.IFS(D31="Common",1,D31="Uncommon",2,D31="Rare",3,D31="Legendary",4,D31="Mythical",5,D31="Event",6)} -> 1 | P31: =_xlfn.CONCAT("('",A31,"',",N31,",",O31,",",E31,",",F31,",",G31,",",H31,",",I31,",","'",J31,"'),") -> ('Grass Carp',1,1,550,5,45,20,95,'Grass Carp eggs require a long river to survive, and the eggs will be considered dead when they hit the bottom of the river.'),
A32: Mud Carp | B32: Freshwater | C32: Carp | D32: Common | E32: 700 | F32: 2 | G32: 5 | H32: 20 | I32: 74 | J32: Mud Carp is considered to be inedible the first time people caught it, but after the great incident, this fish became popular. | K32: Seran, Rosegleam | L32: Dry, Summer, Autumn | M32: Mentari Pond, Seribu Arus River, Saint Luke Pond, Merman Marsh, Wisp Swamp, Sofia River | N32: {=_xlfn.IFS(B32="Freshwater",1,B32="Brackish",2,B32="Seawater",3)} -> 1 | O32: {=_xlfn.IFS(D32="Common",1,D32="Uncommon",2,D32="Rare",3,D32="Legendary",4,D32="Mythical",5,D32="Event",6)} -> 1 | P32: =_xlfn.CONCAT("('",A32,"',",N32,",",O32,",",E32,",",F32,",",G32,",",H32,",",I32,",","'",J32,"'),") -> ('Mud Carp',1,1,700,2,5,20,74,'Mud Carp is considered to be inedible the first time people caught it, but after the great incident, this fish became popular.'),
A33: Mrigal Carp | B33: Freshwater | C33: Carp | D33: Rare | E33: 100 | F33: 2 | G33: 13 | H33: 15 | I33: 100 | J33: This fish live in a lower water level and feeds on small insects and decomposed organic element. | K33: Seran | L33: Dry | M33: Kaca Lake, Seribu Arus River | N33: {=_xlfn.IFS(B33="Freshwater",1,B33="Brackish",2,B33="Seawater",3)} -> 1 | O33: {=_xlfn.IFS(D33="Common",1,D33="Uncommon",2,D33="Rare",3,D33="Legendary",4,D33="Mythical",5,D33="Event",6)} -> 3 | P33: =_xlfn.CONCAT("('",A33,"',",N33,",",O33,",",E33,",",F33,",",G33,",",H33,",",I33,",","'",J33,"'),") -> ('Mrigal Carp',1,3,100,2,13,15,100,'This fish live in a lower water level and feeds on small insects and decomposed organic element.'),
A34: Silver Carp | B34: Freshwater | C34: Carp | D34: Uncommon | E34: 350 | F34: 7 | G34: 50 | H34: 35 | I34: 105 | J34: A fast-growing filter feeder that cruises open freshwater, consuming microscopic plankton and occasionally leaping high above the surface when startled. | K34: Ourea | L34: Spring, Summer, Autumn | M34: Prasinos Creek, Telma Swamp, Evrys River | N34: {=_xlfn.IFS(B34="Freshwater",1,B34="Brackish",2,B34="Seawater",3)} -> 1 | O34: {=_xlfn.IFS(D34="Common",1,D34="Uncommon",2,D34="Rare",3,D34="Legendary",4,D34="Mythical",5,D34="Event",6)} -> 2 | P34: =_xlfn.CONCAT("('",A34,"',",N34,",",O34,",",E34,",",F34,",",G34,",",H34,",",I34,",","'",J34,"'),") -> ('Silver Carp',1,2,350,7,50,35,105,'A fast-growing filter feeder that cruises open freshwater, consuming microscopic plankton and occasionally leaping high above the surface when startled.'),
A35: Black Carp | B35: Freshwater | C35: Carp | D35: Uncommon | E35: 300 | F35: 6 | G35: 35 | H35: 60 | I35: 100 | J35: Black Carp are an elongated fish with a fusiform body. They have a dusky gray, brown, or even bluish black color on their body. | K35: Seran | L35: Monsoon | M35: Seribu Arus River, Mentari Pond, Seroja Marsh | N35: {=_xlfn.IFS(B35="Freshwater",1,B35="Brackish",2,B35="Seawater",3)} -> 1 | O35: {=_xlfn.IFS(D35="Common",1,D35="Uncommon",2,D35="Rare",3,D35="Legendary",4,D35="Mythical",5,D35="Event",6)} -> 2 | P35: =_xlfn.CONCAT("('",A35,"',",N35,",",O35,",",E35,",",F35,",",G35,",",H35,",",I35,",","'",J35,"'),") -> ('Black Carp',1,2,300,6,35,60,100,'Black Carp are an elongated fish with a fusiform body. They have a dusky gray, brown, or even bluish black color on their body.'),
A36: Bighead Carp | B36: Freshwater | C36: Carp | D36: Uncommon | E36: 350 | F36: 9 | G36: 54 | H36: 60 | I36: 146 | J36: The Bighead Carp has a large, scaleless head, a large mouth, and eyes that located very low on their head. | K36: Seran | L36: Dry | M36: Kaca Lake, Seroja Marsh, Batu Kawah Lake, Seroja Darah Swamp | N36: {=_xlfn.IFS(B36="Freshwater",1,B36="Brackish",2,B36="Seawater",3)} -> 1 | O36: {=_xlfn.IFS(D36="Common",1,D36="Uncommon",2,D36="Rare",3,D36="Legendary",4,D36="Mythical",5,D36="Event",6)} -> 2 | P36: =_xlfn.CONCAT("('",A36,"',",N36,",",O36,",",E36,",",F36,",",G36,",",H36,",",I36,",","'",J36,"'),") -> ('Bighead Carp',1,2,350,9,54,60,146,'The Bighead Carp has a large, scaleless head, a large mouth, and eyes that located very low on their head.'),
A37: Giant River Carp | B37: Freshwater | C37: Carp | D37: Uncommon | E37: 325 | F37: 10 | G37: 105 | H37: 30 | I37: 180 | J37: This carp usually lives in a large pond or lake, but seasonally find its way into the canal, reservoir and flooded forest. | K37: Rosegleam | L37: Summer, Autumn | M37: Sofia River | N37: {=_xlfn.IFS(B37="Freshwater",1,B37="Brackish",2,B37="Seawater",3)} -> 1 | O37: {=_xlfn.IFS(D37="Common",1,D37="Uncommon",2,D37="Rare",3,D37="Legendary",4,D37="Mythical",5,D37="Event",6)} -> 2 | P37: =_xlfn.CONCAT("('",A37,"',",N37,",",O37,",",E37,",",F37,",",G37,",",H37,",",I37,",","'",J37,"'),") -> ('Giant River Carp',1,2,325,10,105,30,180,'This carp usually lives in a large pond or lake, but seasonally find its way into the canal, reservoir and flooded forest.'),
A38: Gibel Carp | B38: Freshwater | C38: Carp | D38: Uncommon | E38: 220 | F38: 2 | G38: 5 | H38: 10 | I38: 35 | J38: Gibel Carp reproduce and spread so rapidly that it is said that it can fill an entire medium-sized pond in its species alone. | K38: Tidehaven | L38: Spring, Autumn | M38: Mikill Hvitar Lake, Ormr River, Freyja River | N38: {=_xlfn.IFS(B38="Freshwater",1,B38="Brackish",2,B38="Seawater",3)} -> 1 | O38: {=_xlfn.IFS(D38="Common",1,D38="Uncommon",2,D38="Rare",3,D38="Legendary",4,D38="Mythical",5,D38="Event",6)} -> 2 | P38: =_xlfn.CONCAT("('",A38,"',",N38,",",O38,",",E38,",",F38,",",G38,",",H38,",",I38,",","'",J38,"'),") -> ('Gibel Carp',1,2,220,2,5,10,35,'Gibel Carp reproduce and spread so rapidly that it is said that it can fill an entire medium-sized pond in its species alone.'),
A39: Crucian Carp | B39: Freshwater | C39: Carp | D39: Uncommon | E39: 210 | F39: 1 | G39: 3 | H39: 15 | I39: 64 | J39: This fish mainly lived in nutrient-rich water, but it can also lived in an extreme condition and harsh winter. | K39: Tidehaven | L39: Autumn, Winter | M39: Jotunn Cave, Reyr Marsh, Yrvir Swamp | N39: {=_xlfn.IFS(B39="Freshwater",1,B39="Brackish",2,B39="Seawater",3)} -> 1 | O39: {=_xlfn.IFS(D39="Common",1,D39="Uncommon",2,D39="Rare",3,D39="Legendary",4,D39="Mythical",5,D39="Event",6)} -> 2 | P39: =_xlfn.CONCAT("('",A39,"',",N39,",",O39,",",E39,",",F39,",",G39,",",H39,",",I39,",","'",J39,"'),") -> ('Crucian Carp',1,2,210,1,3,15,64,'This fish mainly lived in nutrient-rich water, but it can also lived in an extreme condition and harsh winter.'),
... A42: Blue Catfish | B42: Freshwater | C42: Catfish | D42: Uncommon | E42: 201 | F42: 9 | G42: 65 | H42: 31 | I42: 180 | J42: Blue Catfish are often misidentified as Channel Catfish, the difference are the heavy bodied, blueish gray in color, and a upper hump. | K42: Ourea, Tidehaven | L42: Summer | M42: Prasinos Creek, Telma Swamp, Evrys River | N42: {=_xlfn.IFS(B42="Freshwater",1,B42="Brackish",2,B42="Seawater",3)} -> 1 | O42: {=_xlfn.IFS(D42="Common",1,D42="Uncommon",2,D42="Rare",3,D42="Legendary",4,D42="Mythical",5,D42="Event",6)} -> 2 | P42: =_xlfn.CONCAT("('",A42,"',",N42,",",O42,",",E42,",",F42,",",G42,",",H42,",",I42,",","'",J42,"'),") -> ('Blue Catfish',1,2,201,9,65,31,180,'Blue Catfish are often misidentified as Channel Catfish, the difference are the heavy bodied, blueish gray in color, and a upper hump.'),
...

Sheet Fish Type
A1: Type | B1: Water
A2: Archer | B2: 2 | C2: =_xlfn.CONCAT("('",A2,"',",B2,"),") -> ('Archer',2),
A3: Bream | B3: 2 | C3: =_xlfn.CONCAT("('",A3,"',",B3,"),") -> ('Bream',2),
A4: Catfish | B4: 2 | C4: =_xlfn.CONCAT("('",A4,"',",B4,"),") -> ('Catfish',2),
A5: Cichlid | B5: 2 | C5: =_xlfn.CONCAT("('",A5,"',",B5,"),") -> ('Cichlid',2),
A6: Flatfish | B6: 2 | C6: =_xlfn.CONCAT("('",A6,"',",B6,"),") -> ('Flatfish',2),
A7: Four Eyed | B7: 2 | C7: =_xlfn.CONCAT("('",A7,"',",B7,"),") -> ('Four Eyed',2),
A8: Goby | B8: 2 | C8: =_xlfn.CONCAT("('",A8,"',",B8,"),") -> ('Goby',2),
A9: Halfbeak | B9: 2 | C9: =_xlfn.CONCAT("('",A9,"',",B9,"),") -> ('Halfbeak',2),
A10: Milkfish | B10: 2 | C10: =_xlfn.CONCAT("('",A10,"',",B10,"),") -> ('Milkfish',2),
A11: Moony | B11: 2 | C11: =_xlfn.CONCAT("('",A11,"',",B11,"),") -> ('Moony',2),
A12: Mullet | B12: 2 | C12: =_xlfn.CONCAT("('",A12,"',",B12,"),") -> ('Mullet',2),
A13: Needlefish | B13: 2 | C13: =_xlfn.CONCAT("('",A13,"',",B13,"),") -> ('Needlefish',2),
... A31: Tuna | B31: 3 | C31: =_xlfn.CONCAT("('",A31,"',",B31,"),") -> ('Tuna',3),

Sheet Mutation
A1: Fish | B1: Name | C1: Chance | D1: Min Weight | E1: Max Weight | F1: Min Length | G1: Max Length | H1: Description | I1: Fish ID
A2: Banded Archerfish | B2: Banded Scalefish | C2: 0.5 | D2: 0.2 | E2: 1.5 | F2: 5 | G2: 15 | H2: A mutated archerfish with scales as hard as a rock to prevent predators from eating them. | I2: =_xlfn.CONCAT("SELECT fish_id FROM fishing.t_fish WHERE fish_name = '",A2,"'") -> SELECT fish_id FROM fishing.t_fish WHERE fish_name = 'Banded Archerfish' | J2: =_xlfn.CONCAT("((",I2,"),","'",B2,"',","'",H2,"',",C2,",",D2,",",E2,",",F2,",",G2,"),") -> ((SELECT fish_id FROM fishing.t_fish WHERE fish_name = 'Banded Archerfish'),'Banded Scalefish','A mutated archerfish with scales as hard as a rock to prevent predators from eating them.',0.5,0.2,1.5,5,15),
A3: Banded Archerfish | B3: Banded Flamefish | C3: 0.5 | D3: 0.5 | E3: 2 | F3: 8 | G3: 20 | H3: An archerfish that shoots hot water to hunt, mana allows it to superheat the water inside its mouth before shooting it. | I3: =_xlfn.CONCAT("SELECT fish_id FROM fishing.t_fish WHERE fish_name = '",A3,"'") -> SELECT fish_id FROM fishing.t_fish WHERE fish_name = 'Banded Archerfish' | J3: =_xlfn.CONCAT("((",I3,"),","'",B3,"',","'",H3,"',",C3,",",D3,",",E3,",",F3,",",G3,"),") -> ((SELECT fish_id FROM fishing.t_fish WHERE fish_name = 'Banded Archerfish'),'Banded Flamefish','An archerfish that shoots hot water to hunt, mana allows it to superheat the water inside its mouth before shooting it.',0.5,0.5,2,8,20),
A4: Northern Archerfish | B4: Horned Archerfish | C4: 0.6 | D4: 0.1 | E4: 1.7 | F4: 4 | G4: 45 | H4: Horned Archerfish uses its horn to defend itself and as a way to attract the female | I4: =_xlfn.CONCAT("SELECT fish_id FROM fishing.t_fish WHERE fish_name = '",A4,"'") -> SELECT fish_id FROM fishing.t_fish WHERE fish_name = 'Northern Archerfish' | J4: =_xlfn.CONCAT("((",I4,"),","'",B4,"',","'",H4,"',",C4,",",D4,",",E4,",",F4,",",G4,"),") -> ((SELECT fish_id FROM fishing.t_fish WHERE fish_name = 'Northern Archerfish'),'Horned Archerfish','Horned Archerfish uses its horn to defend itself and as a way to attract the female',0.6,0.1,1.7,4,45),
A5: Northern Archerfish | B5: Northern Clawfish | C5: 0.4 | D5: 0.3 | E5: 2.2 | F5: 4.5 | G5: 47 | H5: Its fin mutated to have a razor-sharp claw to penetrate the mouth of a fish unfortunate enough to eat it. | I5: =_xlfn.CONCAT("SELECT fish_id FROM fishing.t_fish WHERE fish_name = '",A5,"'") -> SELECT fish_id FROM fishing.t_fish WHERE fish_name = 'Northern Archerfish' | J5: =_xlfn.CONCAT("((",I5,"),","'",B5,"',","'",H5,"',",C5,",",D5,",",E5,",",F5,",",G5,"),") -> ((SELECT fish_id FROM fishing.t_fish WHERE fish_name = 'Northern Archerfish'),'Northern Clawfish','Its fin mutated to have a razor-sharp claw to penetrate the mouth of a fish unfortunate enough to eat it.',0.4,0.3,2.2,4.5,47),
A6: Black Bream | B6: Black-Scale Bream | C6: 0.3 | D6: 0.7 | E6: 5 | F6: 17 | G6: 39 | H6: The scale of this fish mutated to have a scale similar to a dragon's, but not as hard. | I6: =_xlfn.CONCAT("SELECT fish_id FROM fishing.t_fish WHERE fish_name = '",A6,"'") -> SELECT fish_id FROM fishing.t_fish WHERE fish_name = 'Black Bream' | J6: =_xlfn.CONCAT("((",I6,"),","'",B6,"',","'",H6,"',",C6,",",D6,",",E6,",",F6,",",G6,"),") -> ((SELECT fish_id FROM fishing.t_fish WHERE fish_name = 'Black Bream'),'Black-Scale Bream','The scale of this fish mutated to have a scale similar to a dragon's, but not as hard.',0.3,0.7,5,17,39),
A7: Black Bream | B7: Moonlit Bream | C7: 0.7 | D7: 0.6 | E7: 3 | F7: 10 | G7: 24 | H7: Bream that hunt at night, using their faint glow to attract smaller fish to come closer. | I7: =_xlfn.CONCAT("SELECT fish_id FROM fishing.t_fish WHERE fish_name = '",A7,"'") -> SELECT fish_id FROM fishing.t_fish WHERE fish_name = 'Black Bream' | J7: =_xlfn.CONCAT("((",I7,"),","'",B7,"',","'",H7,"',",C7,",",D7,",",E7,",",F7,",",G7,"),") -> ((SELECT fish_id FROM fishing.t_fish WHERE fish_name = 'Black Bream'),'Moonlit Bream','Bream that hunt at night, using their faint glow to attract smaller fish to come closer.',0.7,0.6,3,10,24),
A8: Tarwhine Bream | B8: Mucus Bream | C8: 0.4 | D8: 0.5 | E8: 5 | F8: 15 | G8: 38 | H8: A mucus-covered bream makes its body sleek and slippery; it has a foul taste that discourage predators from eating it. | I8: =_xlfn.CONCAT("SELECT fish_id FROM fishing.t_fish WHERE fish_name = '",A8,"'") -> SELECT fish_id FROM fishing.t_fish WHERE fish_name = 'Tarwhine Bream' | J8: =_xlfn.CONCAT("((",I8,"),","'",B8,"',","'",H8,"',",C8,",",D8,",",E8,",",F8,",",G8,"),") -> ((SELECT fish_id FROM fishing.t_fish WHERE fish_name = 'Tarwhine Bream'),'Mucus Bream','A mucus-covered bream makes its body sleek and slippery; it has a foul taste that discourage predators from eating it.',0.4,0.5,5,15,38),
A9: Tarwhine Bream | B9: Dagger Fang Bream | C9: 0.6 | D9: 1 | E9: 9 | F9: 20 | G9: 60 | H9: A large bream with a dagger-sharp fang, because of this mutation, it became so aggressive that it would attack anything that moved in the water. | I9: =_xlfn.CONCAT("SELECT fish_id FROM fishing.t_fish WHERE fish_name = '",A9,"'") -> SELECT fish_id FROM fishing.t_fish WHERE fish_name = 'Tarwhine Bream' | J9: =_xlfn.CONCAT("((",I9,"),","'",B9,"',","'",H9,"',",C9,",",D9,",",E9,",",F9,",",G9,"),") -> ((SELECT fish_id FROM fishing.t_fish WHERE fish_name = 'Tarwhine Bream'),'Dagger Fang Bream','A large bream with a dagger-sharp fang, because of this mutation, it became so aggressive that it would attack anything that moved in the water.',0.6,1,9,20,60),
A10: Hardhead Catfish | B10: Helmet Catfish | C10: 0.9 | D10: 1 | E10: 4 | F10: 18 | G10: 52 | H10: A catfish that has a head as hard as a soldier's helmet, designed to ram into prey. | I10: =_xlfn.CONCAT("SELECT fish_id FROM fishing.t_fish WHERE fish_name = '",A10,"'") -> SELECT fish_id FROM fishing.t_fish WHERE fish_name = 'Hardhead Catfish' | J10: =_xlfn.CONCAT("((",I10,"),","'",B10,"',","'",H10,"',",C10,",",D10,",",E10,",",F10,",",G10,"),") -> ((SELECT fish_id FROM fishing.t_fish WHERE fish_name = 'Hardhead Catfish'),'Helmet Catfish','A catfish that has a head as hard as a soldier's helmet, designed to ram into prey.',0.9,1,4,18,52),
A11: Hardhead Catfish | B11: Mana-Whiskered Catfish | C11: 0.1 | D11: 0.7 | E11: 3.8 | F11: 12 | G11: 38 | H11: Its whiskers can detect the slightest change in the water, making it extremely hard to catch. | I11: =_xlfn.CONCAT("SELECT fish_id FROM fishing.t_fish WHERE fish_name = '",A11,"'") -> SELECT fish_id FROM fishing.t_fish WHERE fish_name = 'Hardhead Catfish' | J11: =_xlfn.CONCAT("((",I11,"),","'",B11,"',","'",H11,"',",C11,",",D11,",",E11,",",F11,",",G11,"),") -> ((SELECT fish_id FROM fishing.t_fish WHERE fish_name = 'Hardhead Catfish'),'Mana-Whiskered Catfish','Its whiskers can detect the slightest change in the water, making it extremely hard to catch.',0.1,0.7,3.8,12,38),
A12: Gafftopsail Catfish | B12: Bloodeye Catfish | C12: 0.3 | D12: 0.7 | E12: 3 | F12: 7 | G12: 26 | H12: This catfish has a red eye that enables it to see exceptionally well in a low-light area. Fishermen usually save its eyes for luck. | I12: =_xlfn.CONCAT("SELECT fish_id FROM fishing.t_fish WHERE fish_name = '",A12,"'") -> SELECT fish_id FROM fishing.t_fish WHERE fish_name = 'Gafftopsail Catfish' | J12: =_xlfn.CONCAT("((",I12,"),","'",B12,"',","'",H12,"',",C12,",",D12,",",E12,",",F12,",",G12,"),") -> ((SELECT fish_id FROM fishing.t_fish WHERE fish_name = 'Gafftopsail Catfish'),'Bloodeye Catfish','This catfish has a red eye that enables it to see exceptionally well in a low-light area. Fishermen usually save its eyes for luck.',0.3,0.7,3,7,26),
A13: Gafftopsail Catfish | B13: Venomous Catfish | C13: 0.7 | D13: 1.5 | E13: 4.5 | F13: 15 | G13: 45 | H13: Its tail fin becomes so venomous that its venom has claimed many careless fishermen. | I13: =_xlfn.CONCAT("SELECT fish_id FROM fishing.t_fish WHERE fish_name = '",A13,"'") -> SELECT fish_id FROM fishing.t_fish WHERE fish_name = 'Gafftopsail Catfish' | J13: =_xlfn.CONCAT("((",I13,"),","'",B13,"',","'",H13,"',",C13,",",D13,",",E13,",",F13,",",G13,"),") -> ((SELECT fish_id FROM fishing.t_fish WHERE fish_name = 'Gafftopsail Catfish'),'Venomous Catfish','Its tail fin becomes so venomous that its venom has claimed many careless fishermen.',0.7,1.5,4.5,15,45),
